WARNING 2025-05-24 15:20:08,131 /home/ali/Desktop/Django/ChatBox/.venv/lib/python3.13/site-packages/django/utils/log.py log 241 - Not Found: /
WARNING 2025-05-24 15:20:08,131 /home/ali/Desktop/Django/ChatBox/.venv/lib/python3.13/site-packages/django/core/servers/basehttp.py basehttp 212 - "GET / HTTP/1.1" 404 2058
WARNING 2025-05-24 15:20:08,224 /home/ali/Desktop/Django/ChatBox/.venv/lib/python3.13/site-packages/django/utils/log.py log 241 - Not Found: /favicon.ico
WARNING 2025-05-24 15:20:08,225 /home/ali/Desktop/Django/ChatBox/.venv/lib/python3.13/site-packages/django/core/servers/basehttp.py basehttp 212 - "GET /favicon.ico HTTP/1.1" 404 2109
WARNING 2025-05-24 15:20:12,363 /home/ali/Desktop/Django/ChatBox/.venv/lib/python3.13/site-packages/django/utils/log.py log 241 - Not Found: /admin/
WARNING 2025-05-24 15:20:12,364 /home/ali/Desktop/Django/ChatBox/.venv/lib/python3.13/site-packages/django/core/servers/basehttp.py basehttp 212 - "GET /admin/ HTTP/1.1" 404 2094
CRITICAL 2025-05-24 15:21:49,487 /home/ali/Desktop/Django/ChatBox/src/auth_module/views.py views 144 - relation "token_blacklist_outstandingtoken" does not exist
LINE 1: INSERT INTO "token_blacklist_outstandingtoken" ("user_id", "...
                    ^
Traceback (most recent call last):
  File "/home/ali/Desktop/Django/ChatBox/.venv/lib/python3.13/site-packages/django/db/backends/utils.py", line 105, in _execute
    return self.cursor.execute(sql, params)
           ~~~~~~~~~~~~~~~~~~~^^^^^^^^^^^^^
psycopg2.errors.UndefinedTable: relation "token_blacklist_outstandingtoken" does not exist
LINE 1: INSERT INTO "token_blacklist_outstandingtoken" ("user_id", "...
                    ^


The above exception was the direct cause of the following exception:

Traceback (most recent call last):
  File "/home/ali/Desktop/Django/ChatBox/src/auth_module/views.py", line 131, in post
    response = super().post(request, *args, **kwargs)
  File "/home/ali/Desktop/Django/ChatBox/.venv/lib/python3.13/site-packages/rest_framework_simplejwt/views.py", line 44, in post
    serializer.is_valid(raise_exception=True)
    ~~~~~~~~~~~~~~~~~~~^^^^^^^^^^^^^^^^^^^^^^
  File "/home/ali/Desktop/Django/ChatBox/.venv/lib/python3.13/site-packages/rest_framework/serializers.py", line 225, in is_valid
    self._validated_data = self.run_validation(self.initial_data)
                           ~~~~~~~~~~~~~~~~~~~^^^^^^^^^^^^^^^^^^^
  File "/home/ali/Desktop/Django/ChatBox/.venv/lib/python3.13/site-packages/rest_framework/serializers.py", line 447, in run_validation
    value = self.validate(value)
  File "/home/ali/Desktop/Django/ChatBox/.venv/lib/python3.13/site-packages/rest_framework_simplejwt/serializers.py", line 75, in validate
    refresh = self.get_token(self.user)
  File "/home/ali/Desktop/Django/ChatBox/src/auth_module/serializer.py", line 54, in get_token
    token = super().get_token(user)
  File "/home/ali/Desktop/Django/ChatBox/.venv/lib/python3.13/site-packages/rest_framework_simplejwt/serializers.py", line 66, in get_token
    return cls.token_class.for_user(user)  # type: ignore
           ~~~~~~~~~~~~~~~~~~~~~~~~^^^^^^
  File "/home/ali/Desktop/Django/ChatBox/.venv/lib/python3.13/site-packages/rest_framework_simplejwt/tokens.py", line 331, in for_user
    OutstandingToken.objects.create(
    ~~~~~~~~~~~~~~~~~~~~~~~~~~~~~~~^
        user=user,
        ^^^^^^^^^^
    ...<3 lines>...
        expires_at=datetime_from_epoch(exp),
        ^^^^^^^^^^^^^^^^^^^^^^^^^^^^^^^^^^^^
    )
    ^
  File "/home/ali/Desktop/Django/ChatBox/.venv/lib/python3.13/site-packages/django/db/models/manager.py", line 87, in manager_method
    return getattr(self.get_queryset(), name)(*args, **kwargs)
           ~~~~~~~~~~~~~~~~~~~~~~~~~~~~~~~~~~^^^^^^^^^^^^^^^^^
  File "/home/ali/Desktop/Django/ChatBox/.venv/lib/python3.13/site-packages/django/db/models/query.py", line 677, in create
    obj.save(force_insert=True, using=self.db)
    ~~~~~~~~^^^^^^^^^^^^^^^^^^^^^^^^^^^^^^^^^^
  File "/home/ali/Desktop/Django/ChatBox/.venv/lib/python3.13/site-packages/django/db/models/base.py", line 814, in save
    self.save_base(
    ~~~~~~~~~~~~~~^
        using=using,
        ^^^^^^^^^^^^
    ...<2 lines>...
        update_fields=update_fields,
        ^^^^^^^^^^^^^^^^^^^^^^^^^^^^
    )
    ^
  File "/home/ali/Desktop/Django/ChatBox/.venv/lib/python3.13/site-packages/django/db/models/base.py", line 901, in save_base
    updated = self._save_table(
        raw,
    ...<4 lines>...
        update_fields,
    )
  File "/home/ali/Desktop/Django/ChatBox/.venv/lib/python3.13/site-packages/django/db/models/base.py", line 1059, in _save_table
    results = self._do_insert(
        cls._base_manager, using, fields, returning_fields, raw
    )
  File "/home/ali/Desktop/Django/ChatBox/.venv/lib/python3.13/site-packages/django/db/models/base.py", line 1100, in _do_insert
    return manager._insert(
           ~~~~~~~~~~~~~~~^
        [self],
        ^^^^^^^
    ...<3 lines>...
        raw=raw,
        ^^^^^^^^
    )
    ^
  File "/home/ali/Desktop/Django/ChatBox/.venv/lib/python3.13/site-packages/django/db/models/manager.py", line 87, in manager_method
    return getattr(self.get_queryset(), name)(*args, **kwargs)
           ~~~~~~~~~~~~~~~~~~~~~~~~~~~~~~~~~~^^^^^^^^^^^^^^^^^
  File "/home/ali/Desktop/Django/ChatBox/.venv/lib/python3.13/site-packages/django/db/models/query.py", line 1845, in _insert
    return query.get_compiler(using=using).execute_sql(returning_fields)
           ~~~~~~~~~~~~~~~~~~~~~~~~~~~~~~~~~~~~~~~~~~~^^^^^^^^^^^^^^^^^^
  File "/home/ali/Desktop/Django/ChatBox/.venv/lib/python3.13/site-packages/django/db/models/sql/compiler.py", line 1822, in execute_sql
    cursor.execute(sql, params)
    ~~~~~~~~~~~~~~^^^^^^^^^^^^^
  File "/home/ali/Desktop/Django/ChatBox/.venv/lib/python3.13/site-packages/django/db/backends/utils.py", line 122, in execute
    return super().execute(sql, params)
           ~~~~~~~~~~~~~~~^^^^^^^^^^^^^
  File "/home/ali/Desktop/Django/ChatBox/.venv/lib/python3.13/site-packages/django/db/backends/utils.py", line 79, in execute
    return self._execute_with_wrappers(
           ~~~~~~~~~~~~~~~~~~~~~~~~~~~^
        sql, params, many=False, executor=self._execute
        ^^^^^^^^^^^^^^^^^^^^^^^^^^^^^^^^^^^^^^^^^^^^^^^
    )
    ^
  File "/home/ali/Desktop/Django/ChatBox/.venv/lib/python3.13/site-packages/django/db/backends/utils.py", line 92, in _execute_with_wrappers
    return executor(sql, params, many, context)
  File "/home/ali/Desktop/Django/ChatBox/.venv/lib/python3.13/site-packages/django/db/backends/utils.py", line 100, in _execute
    with self.db.wrap_database_errors:
         ^^^^^^^^^^^^^^^^^^^^^^^^^^^^
  File "/home/ali/Desktop/Django/ChatBox/.venv/lib/python3.13/site-packages/django/db/utils.py", line 91, in __exit__
    raise dj_exc_value.with_traceback(traceback) from exc_value
  File "/home/ali/Desktop/Django/ChatBox/.venv/lib/python3.13/site-packages/django/db/backends/utils.py", line 105, in _execute
    return self.cursor.execute(sql, params)
           ~~~~~~~~~~~~~~~~~~~^^^^^^^^^^^^^
django.db.utils.ProgrammingError: relation "token_blacklist_outstandingtoken" does not exist
LINE 1: INSERT INTO "token_blacklist_outstandingtoken" ("user_id", "...
                    ^

WARNING 2025-05-24 15:21:49,497 /home/ali/Desktop/Django/ChatBox/.venv/lib/python3.13/site-packages/django/utils/log.py log 241 - Bad Request: /api/auth/token/
WARNING 2025-05-24 15:21:49,497 /home/ali/Desktop/Django/ChatBox/.venv/lib/python3.13/site-packages/django/core/servers/basehttp.py basehttp 212 - "POST /api/auth/token/ HTTP/1.1" 400 61
WARNING 2025-05-24 15:25:53,740 /home/ali/Desktop/Django/ChatBox/.venv/lib/python3.13/site-packages/django/utils/log.py log 241 - Too Many Requests: /api/auth/otp/
WARNING 2025-05-24 15:25:53,740 /home/ali/Desktop/Django/ChatBox/.venv/lib/python3.13/site-packages/django/core/servers/basehttp.py basehttp 212 - "POST /api/auth/otp/ HTTP/1.1" 429 55
WARNING 2025-05-24 15:26:38,492 /home/ali/Desktop/Django/ChatBox/.venv/lib/python3.13/site-packages/django/utils/log.py log 241 - Too Many Requests: /api/auth/otp/
WARNING 2025-05-24 15:26:38,492 /home/ali/Desktop/Django/ChatBox/.venv/lib/python3.13/site-packages/django/core/servers/basehttp.py basehttp 212 - "POST /api/auth/otp/ HTTP/1.1" 429 38
WARNING 2025-05-24 15:27:39,085 /home/ali/Desktop/Django/ChatBox/.venv/lib/python3.13/site-packages/django/utils/log.py log 241 - Too Many Requests: /api/auth/otp/
WARNING 2025-05-24 15:27:39,085 /home/ali/Desktop/Django/ChatBox/.venv/lib/python3.13/site-packages/django/core/servers/basehttp.py basehttp 212 - "POST /api/auth/otp/ HTTP/1.1" 429 38
WARNING 2025-05-24 15:27:41,921 /home/ali/Desktop/Django/ChatBox/.venv/lib/python3.13/site-packages/django/utils/log.py log 241 - Too Many Requests: /api/auth/otp/
WARNING 2025-05-24 15:27:41,922 /home/ali/Desktop/Django/ChatBox/.venv/lib/python3.13/site-packages/django/core/servers/basehttp.py basehttp 212 - "POST /api/auth/otp/ HTTP/1.1" 429 38
WARNING 2025-05-24 15:29:30,136 /home/ali/Desktop/Django/ChatBox/.venv/lib/python3.13/site-packages/django/utils/log.py log 241 - Too Many Requests: /api/auth/otp/
WARNING 2025-05-24 15:29:30,137 /home/ali/Desktop/Django/ChatBox/.venv/lib/python3.13/site-packages/django/core/servers/basehttp.py basehttp 212 - "POST /api/auth/otp/ HTTP/1.1" 429 38
WARNING 2025-05-24 15:29:51,011 /home/ali/Desktop/Django/ChatBox/.venv/lib/python3.13/site-packages/django/utils/log.py log 241 - Too Many Requests: /api/auth/otp/
WARNING 2025-05-24 15:29:51,011 /home/ali/Desktop/Django/ChatBox/.venv/lib/python3.13/site-packages/django/core/servers/basehttp.py basehttp 212 - "POST /api/auth/otp/ HTTP/1.1" 429 38
ERROR 2025-05-24 15:30:48,192 /home/ali/Desktop/Django/ChatBox/.venv/lib/python3.13/site-packages/django/utils/log.py log 241 - Internal Server Error: /api/auth/otp/
Traceback (most recent call last):
  File "/home/ali/Desktop/Django/ChatBox/.venv/lib/python3.13/site-packages/django/db/backends/utils.py", line 105, in _execute
    return self.cursor.execute(sql, params)
           ~~~~~~~~~~~~~~~~~~~^^^^^^^^^^^^^
psycopg2.errors.UndefinedTable: relation "token_blacklist_outstandingtoken" does not exist
LINE 1: INSERT INTO "token_blacklist_outstandingtoken" ("user_id", "...
                    ^


The above exception was the direct cause of the following exception:

Traceback (most recent call last):
  File "/home/ali/Desktop/Django/ChatBox/.venv/lib/python3.13/site-packages/django/core/handlers/exception.py", line 55, in inner
    response = get_response(request)
  File "/home/ali/Desktop/Django/ChatBox/.venv/lib/python3.13/site-packages/django/core/handlers/base.py", line 197, in _get_response
    response = wrapped_callback(request, *callback_args, **callback_kwargs)
  File "/home/ali/Desktop/Django/ChatBox/.venv/lib/python3.13/site-packages/django/views/decorators/csrf.py", line 65, in _view_wrapper
    return view_func(request, *args, **kwargs)
  File "/home/ali/Desktop/Django/ChatBox/.venv/lib/python3.13/site-packages/django/views/generic/base.py", line 104, in view
    return self.dispatch(request, *args, **kwargs)
           ~~~~~~~~~~~~~^^^^^^^^^^^^^^^^^^^^^^^^^^
  File "/home/ali/Desktop/Django/ChatBox/.venv/lib/python3.13/site-packages/rest_framework/views.py", line 515, in dispatch
    response = self.handle_exception(exc)
  File "/home/ali/Desktop/Django/ChatBox/.venv/lib/python3.13/site-packages/rest_framework/views.py", line 475, in handle_exception
    self.raise_uncaught_exception(exc)
    ~~~~~~~~~~~~~~~~~~~~~~~~~~~~~^^^^^
  File "/home/ali/Desktop/Django/ChatBox/.venv/lib/python3.13/site-packages/rest_framework/views.py", line 486, in raise_uncaught_exception
    raise exc
  File "/home/ali/Desktop/Django/ChatBox/.venv/lib/python3.13/site-packages/rest_framework/views.py", line 512, in dispatch
    response = handler(request, *args, **kwargs)
  File "/home/ali/Desktop/Django/ChatBox/src/auth_module/views.py", line 104, in put
    refresh_token = str(RefreshToken.for_user(user))
                        ~~~~~~~~~~~~~~~~~~~~~^^^^^^
  File "/home/ali/Desktop/Django/ChatBox/.venv/lib/python3.13/site-packages/rest_framework_simplejwt/tokens.py", line 331, in for_user
    OutstandingToken.objects.create(
    ~~~~~~~~~~~~~~~~~~~~~~~~~~~~~~~^
        user=user,
        ^^^^^^^^^^
    ...<3 lines>...
        expires_at=datetime_from_epoch(exp),
        ^^^^^^^^^^^^^^^^^^^^^^^^^^^^^^^^^^^^
    )
    ^
  File "/home/ali/Desktop/Django/ChatBox/.venv/lib/python3.13/site-packages/django/db/models/manager.py", line 87, in manager_method
    return getattr(self.get_queryset(), name)(*args, **kwargs)
           ~~~~~~~~~~~~~~~~~~~~~~~~~~~~~~~~~~^^^^^^^^^^^^^^^^^
  File "/home/ali/Desktop/Django/ChatBox/.venv/lib/python3.13/site-packages/django/db/models/query.py", line 677, in create
    obj.save(force_insert=True, using=self.db)
    ~~~~~~~~^^^^^^^^^^^^^^^^^^^^^^^^^^^^^^^^^^
  File "/home/ali/Desktop/Django/ChatBox/.venv/lib/python3.13/site-packages/django/db/models/base.py", line 814, in save
    self.save_base(
    ~~~~~~~~~~~~~~^
        using=using,
        ^^^^^^^^^^^^
    ...<2 lines>...
        update_fields=update_fields,
        ^^^^^^^^^^^^^^^^^^^^^^^^^^^^
    )
    ^
  File "/home/ali/Desktop/Django/ChatBox/.venv/lib/python3.13/site-packages/django/db/models/base.py", line 901, in save_base
    updated = self._save_table(
        raw,
    ...<4 lines>...
        update_fields,
    )
  File "/home/ali/Desktop/Django/ChatBox/.venv/lib/python3.13/site-packages/django/db/models/base.py", line 1059, in _save_table
    results = self._do_insert(
        cls._base_manager, using, fields, returning_fields, raw
    )
  File "/home/ali/Desktop/Django/ChatBox/.venv/lib/python3.13/site-packages/django/db/models/base.py", line 1100, in _do_insert
    return manager._insert(
           ~~~~~~~~~~~~~~~^
        [self],
        ^^^^^^^
    ...<3 lines>...
        raw=raw,
        ^^^^^^^^
    )
    ^
  File "/home/ali/Desktop/Django/ChatBox/.venv/lib/python3.13/site-packages/django/db/models/manager.py", line 87, in manager_method
    return getattr(self.get_queryset(), name)(*args, **kwargs)
           ~~~~~~~~~~~~~~~~~~~~~~~~~~~~~~~~~~^^^^^^^^^^^^^^^^^
  File "/home/ali/Desktop/Django/ChatBox/.venv/lib/python3.13/site-packages/django/db/models/query.py", line 1845, in _insert
    return query.get_compiler(using=using).execute_sql(returning_fields)
           ~~~~~~~~~~~~~~~~~~~~~~~~~~~~~~~~~~~~~~~~~~~^^^^^^^^^^^^^^^^^^
  File "/home/ali/Desktop/Django/ChatBox/.venv/lib/python3.13/site-packages/django/db/models/sql/compiler.py", line 1822, in execute_sql
    cursor.execute(sql, params)
    ~~~~~~~~~~~~~~^^^^^^^^^^^^^
  File "/home/ali/Desktop/Django/ChatBox/.venv/lib/python3.13/site-packages/django/db/backends/utils.py", line 122, in execute
    return super().execute(sql, params)
           ~~~~~~~~~~~~~~~^^^^^^^^^^^^^
  File "/home/ali/Desktop/Django/ChatBox/.venv/lib/python3.13/site-packages/django/db/backends/utils.py", line 79, in execute
    return self._execute_with_wrappers(
           ~~~~~~~~~~~~~~~~~~~~~~~~~~~^
        sql, params, many=False, executor=self._execute
        ^^^^^^^^^^^^^^^^^^^^^^^^^^^^^^^^^^^^^^^^^^^^^^^
    )
    ^
  File "/home/ali/Desktop/Django/ChatBox/.venv/lib/python3.13/site-packages/django/db/backends/utils.py", line 92, in _execute_with_wrappers
    return executor(sql, params, many, context)
  File "/home/ali/Desktop/Django/ChatBox/.venv/lib/python3.13/site-packages/django/db/backends/utils.py", line 100, in _execute
    with self.db.wrap_database_errors:
         ^^^^^^^^^^^^^^^^^^^^^^^^^^^^
  File "/home/ali/Desktop/Django/ChatBox/.venv/lib/python3.13/site-packages/django/db/utils.py", line 91, in __exit__
    raise dj_exc_value.with_traceback(traceback) from exc_value
  File "/home/ali/Desktop/Django/ChatBox/.venv/lib/python3.13/site-packages/django/db/backends/utils.py", line 105, in _execute
    return self.cursor.execute(sql, params)
           ~~~~~~~~~~~~~~~~~~~^^^^^^^^^^^^^
django.db.utils.ProgrammingError: relation "token_blacklist_outstandingtoken" does not exist
LINE 1: INSERT INTO "token_blacklist_outstandingtoken" ("user_id", "...
                    ^

ERROR 2025-05-24 15:30:48,198 /home/ali/Desktop/Django/ChatBox/.venv/lib/python3.13/site-packages/django/core/servers/basehttp.py basehttp 212 - "PUT /api/auth/otp/ HTTP/1.1" 500 198616
WARNING 2025-05-24 15:34:05,340 /home/ali/Desktop/Django/ChatBox/.venv/lib/python3.13/site-packages/django/utils/log.py log 241 - Method Not Allowed: /api/auth/token/
WARNING 2025-05-24 15:34:05,341 /home/ali/Desktop/Django/ChatBox/.venv/lib/python3.13/site-packages/django/core/servers/basehttp.py basehttp 212 - "GET /api/auth/token/ HTTP/1.1" 405 40
WARNING 2025-05-24 15:34:35,451 /home/ali/Desktop/Django/ChatBox/.venv/lib/python3.13/site-packages/django/utils/log.py log 241 - Unauthorized: /api/auth/token/verify/
WARNING 2025-05-24 15:34:35,451 /home/ali/Desktop/Django/ChatBox/.venv/lib/python3.13/site-packages/django/core/servers/basehttp.py basehttp 212 - "POST /api/auth/token/verify/ HTTP/1.1" 401 58
WARNING 2025-05-24 15:35:17,434 /home/ali/Desktop/Django/ChatBox/.venv/lib/python3.13/site-packages/django/utils/log.py log 241 - Method Not Allowed: /api/auth/token/verify/
WARNING 2025-05-24 15:35:17,435 /home/ali/Desktop/Django/ChatBox/.venv/lib/python3.13/site-packages/django/core/servers/basehttp.py basehttp 212 - "POST /api/auth/token/verify/ HTTP/1.1" 405 41
WARNING 2025-05-24 15:37:30,085 /home/ali/Desktop/Django/ChatBox/.venv/lib/python3.13/site-packages/django/utils/log.py log 241 - Method Not Allowed: /api/auth/logout/
WARNING 2025-05-24 15:37:30,085 /home/ali/Desktop/Django/ChatBox/.venv/lib/python3.13/site-packages/django/core/servers/basehttp.py basehttp 212 - "GET /api/auth/logout/ HTTP/1.1" 405 40
CRITICAL 2025-05-24 15:37:34,049 /home/ali/Desktop/Django/ChatBox/src/auth_module/views.py views 181 - 'refresh'
Traceback (most recent call last):
  File "/home/ali/Desktop/Django/ChatBox/src/auth_module/views.py", line 176, in post
    refresh_token = request.data["refresh"]
                    ~~~~~~~~~~~~^^^^^^^^^^^
KeyError: 'refresh'
WARNING 2025-05-24 15:37:34,050 /home/ali/Desktop/Django/ChatBox/.venv/lib/python3.13/site-packages/django/utils/log.py log 241 - Bad Request: /api/auth/logout/
WARNING 2025-05-24 15:37:34,051 /home/ali/Desktop/Django/ChatBox/.venv/lib/python3.13/site-packages/django/core/servers/basehttp.py basehttp 212 - "POST /api/auth/logout/ HTTP/1.1" 400 61
CRITICAL 2025-05-24 15:38:13,921 /home/ali/Desktop/Django/ChatBox/src/auth_module/views.py views 181 - Token is blacklisted
Traceback (most recent call last):
  File "/home/ali/Desktop/Django/ChatBox/src/auth_module/views.py", line 177, in post
    token = RefreshToken(refresh_token)
  File "/home/ali/Desktop/Django/ChatBox/.venv/lib/python3.13/site-packages/rest_framework_simplejwt/tokens.py", line 71, in __init__
    self.verify()
    ~~~~~~~~~~~^^
  File "/home/ali/Desktop/Django/ChatBox/.venv/lib/python3.13/site-packages/rest_framework_simplejwt/tokens.py", line 280, in verify
    self.check_blacklist()
    ~~~~~~~~~~~~~~~~~~~~^^
  File "/home/ali/Desktop/Django/ChatBox/.venv/lib/python3.13/site-packages/rest_framework_simplejwt/tokens.py", line 292, in check_blacklist
    raise TokenError(_("Token is blacklisted"))
rest_framework_simplejwt.exceptions.TokenError: Token is blacklisted
WARNING 2025-05-24 15:38:13,923 /home/ali/Desktop/Django/ChatBox/.venv/lib/python3.13/site-packages/django/utils/log.py log 241 - Bad Request: /api/auth/logout/
WARNING 2025-05-24 15:38:13,923 /home/ali/Desktop/Django/ChatBox/.venv/lib/python3.13/site-packages/django/core/servers/basehttp.py basehttp 212 - "POST /api/auth/logout/ HTTP/1.1" 400 61
CRITICAL 2025-05-24 15:38:38,142 /home/ali/Desktop/Django/ChatBox/src/auth_module/views.py views 181 - Token is blacklisted
Traceback (most recent call last):
  File "/home/ali/Desktop/Django/ChatBox/src/auth_module/views.py", line 177, in post
    token = RefreshToken(refresh_token)
  File "/home/ali/Desktop/Django/ChatBox/.venv/lib/python3.13/site-packages/rest_framework_simplejwt/tokens.py", line 71, in __init__
    self.verify()
    ~~~~~~~~~~~^^
  File "/home/ali/Desktop/Django/ChatBox/.venv/lib/python3.13/site-packages/rest_framework_simplejwt/tokens.py", line 280, in verify
    self.check_blacklist()
    ~~~~~~~~~~~~~~~~~~~~^^
  File "/home/ali/Desktop/Django/ChatBox/.venv/lib/python3.13/site-packages/rest_framework_simplejwt/tokens.py", line 292, in check_blacklist
    raise TokenError(_("Token is blacklisted"))
rest_framework_simplejwt.exceptions.TokenError: Token is blacklisted
WARNING 2025-05-24 15:38:38,143 /home/ali/Desktop/Django/ChatBox/.venv/lib/python3.13/site-packages/django/utils/log.py log 241 - Bad Request: /api/auth/logout/
WARNING 2025-05-24 15:38:38,144 /home/ali/Desktop/Django/ChatBox/.venv/lib/python3.13/site-packages/django/core/servers/basehttp.py basehttp 212 - "POST /api/auth/logout/ HTTP/1.1" 400 61
CRITICAL 2025-05-24 16:10:10,209 /home/ali/Desktop/Django/ChatBox/src/private_module/consumers.py consumers 14 - SSSssssssSSSSSS, ssdf
CRITICAL 2025-05-24 16:14:15,510 /home/ali/Desktop/Django/ChatBox/src/private_module/consumers.py consumers 18 - 09121540661
CRITICAL 2025-05-24 16:14:29,384 /home/ali/Desktop/Django/ChatBox/src/private_module/consumers.py consumers 18 - 11
CRITICAL 2025-05-24 16:14:30,533 /home/ali/Desktop/Django/ChatBox/src/private_module/consumers.py consumers 18 - 11
CRITICAL 2025-05-24 16:26:42,495 /home/ali/Desktop/Django/ChatBox/src/private_module/consumers.py consumers 29 - heeey
WARNING 2025-05-24 16:33:36,595 /home/ali/Desktop/Django/ChatBox/src/private_module/consumers.py consumers 34 - string indices must be integers, not 'str'
Traceback (most recent call last):
  File "/home/ali/Desktop/Django/ChatBox/src/private_module/consumers.py", line 29, in receive
    _ = text_data["message"]
        ~~~~~~~~~^^^^^^^^^^^
TypeError: string indices must be integers, not 'str'
WARNING 2025-05-24 16:34:01,316 /home/ali/Desktop/Django/ChatBox/src/private_module/consumers.py consumers 33 - string indices must be integers, not 'str'
Traceback (most recent call last):
  File "/home/ali/Desktop/Django/ChatBox/src/private_module/consumers.py", line 28, in receive
    _ = text_data["message"]
        ~~~~~~~~~^^^^^^^^^^^
TypeError: string indices must be integers, not 'str'
WARNING 2025-05-24 16:34:18,171 /home/ali/Desktop/Django/ChatBox/src/private_module/consumers.py consumers 34 - string indices must be integers, not 'str'
Traceback (most recent call last):
  File "/home/ali/Desktop/Django/ChatBox/src/private_module/consumers.py", line 28, in receive
    _ = text_data["message"]
        ~~~~~~~~~^^^^^^^^^^^
TypeError: string indices must be integers, not 'str'
